Workbook

Sheet All Research
A1: COURTESY OF THE GLOBAL MOTHER DIVINE ORGANIZATION® | H1: Research Publications on
A2: Please email inquiries to: tmresearchspreadsheet@tm-women.org | H2: Transcendental Meditation® and TM-Sidhi Programs®
H3: Bibliography 1970–2026∗
H4: This spreadsheet (database) prepared by Jean Tobin, of the Global Mother Divine Organization, compiles summaries, abstracts, and data on study design and results for 485 papers published in peer-reviewed journals or other independent edited scientific publications. Most of these papers report original studies or reviews of research; a small number provide important comment or clarification regarding specific studies, including responses to critiques. A few studies examine a comprehensive multimodal approach to health that includes Transcendental Meditation®. Transcendental Meditation®, TM®, and TM-Sidhi® are protected trademarks and are used in the U.S. under license or with permission *Bibliography of research publications on Transcendental Meditation® compiled by Dr Roger Chalmers MRCP(UK) MRCGP DRCOG
H6: Column A: General Topic: Health, Mental Potential Social Behavior, World Peace
H7: Column B: Field and Collected Papers Reference (if applicable): Physiological, Psychological, Sociological
H8: Column C: Specialty Area: Academic Performance, Affective, Biochemical, Cardiovascular, Cognitive, Development of Personality, EEG, Electrophysiological, Education, Electrophysiological, Health, Intelligence, Learning, Metabolic, Motor and Perceptual, Physiological Efficiency and Stability, Productivity and Quality of Life, Rehabilitation, Review of Research
H9: Column D: Specific Results
H10: Column E: Randomized controlled trial/ Meta-analysis
H11: Column F: Year Published
H12: Column G s = Summary provided
H13: Column H: Citation/Abstract/Summary
A14: GENERAL TOPIC | B14: FIELD and Collected Papers Reference | C14: SPECIALTY AREA | D14: SPECIFIC RESULTS | E14: RCT /META | F14: YEAR
A15: Social Behavior | B15: Sociological CPVol 3Pg 2093 | C15: Rehabilitation | D15: Reduced Insomnia TM in Corrections | F15: 1978 | G15: s | H15: Abrams AI, Siegel LM. The Transcendental Meditation program and rehabilitation at Folsom State Prison: a cross-validation study. Criminal Justice and Behavior 1978 5(1):3-20 The Transcendental Meditation program in a maximum security prison was studied via cross-validation design. Significant differences were found between the Transcendental Meditation and control groups across all the inventories, indicating reduction in anxiety, neuroticism, hostility, insomnia, fewer behavior infractions, decreased resentment; decreased negativism decreased irritability; improved sleep patterns (decreased time to fall asleep, decreased awakenings per night, improved quality of sleep).
A16: Social Behavior | B16: Sociological CPVol 3Pg 2104 | C16: Rehabilitation | D16: TM in Corrections | F16: 1979 | G16: s | H16: Abrams AI, Siegel LM Transcendental Meditation and rehabilitation at Folsom Prison: response to a critique. Criminal Justice and Behavior 1979 6(1):13-21 The benefits of Transcendental Meditation reported in the previous paper were found not to be the result of selection bias or a tendency of subjects to make socially desirable, untrue responses. The article responds to the challenge posed that findings by Abrams and Siegel on the TM program at Folsom State Prison resulted from Rosenthal experimental bias effects, and that the data was parsimoniously interpreted by the authors. The authors noted that Rosenthal effects are not so pervasive that in every possible instance promising treatments should be discounted. Moreover, EPI Lie Scale data indicate that, if anything, the treatment reduced the inmates' modest tendency to make socially desirable, untrue responses. No consistent relations between levels of Lie Scale and criterion variables were found in a meta-analysis of the data. In conclusion, the potential cost effectiveness of the program, which was questioned by the critic, was supported by an analysis of preliminary recidivism rates of discharged participants.
A17: Health | B17: Physiological | C17: Cardiovascular | D17: Reduced Hypertension | F17: 1981 | G17: s | H17: Agarwal BL, Kharbanda A. Effect of transcendental meditation on mild and moderate hypertension. Journal of the Association of Physicians of India 1981 29:591-596 Reductions in systolic and diastolic blood pressure were found in mild and moderately hypertensive subjects after six months of practice of the Transcendental Meditation technique. It is suggested that Transcendental Meditation may be used as the primary treatment in such cases. Reduction of high blood pressure is of great importance for the prevention of cardiovascular disease. Sixteen patients with mild to moderate essential hypertension undertook a carefully supervised program of Transcendental Meditation (TM). After six months, there were falls in mean systolic, diastolic, and mean arterial pressures of 16.75, 9.81, and 12.12 respectively which were highly significant. Ten (62.5%) of the 16 patients were considered to have responded satisfactorily as they showed a fall of mean arterial pressure by 15 mmHg or more, or a diastolic blood pressure of less than 90 mmHg. Results are comparable to treatment with drugs. Most of the reduction in pressure took place in the first two months. A feeling of well-being was reported by nearly all the subjects.
A18: Mental Potential | B18: Psychological: Review CPVol 6 Pg 4385 | C18: Review of Research | D18: Review of Effects on Indiv & Society | F18: 1994 | G18: s | H18: Alexander CN. Transcendental Meditation. In RJ Corsini (ed.), Encyclopedia of Psychology (pp.5465-5466). New York: Wiley Interscience, 1994 This paper presents an introduction to the Transcendental Meditation Program and major scientific research findings on its effects for the individual and society.
A19: Mental Potential & Health | B19: Psychological: Review CPVol5 Pg3399 | C19: Development of Personality | D19: TC | F19: 1986 | G19: s | H19: Alexander CN, Cranson RW, Boyer RW, Orme-Johnson DW. Transcendental Consciousness: a fourth state of consciousness beyond sleep, dreaming, and waking. In J Gackenbach (ed.), Sleep and Dreams: A Sourcebook (pp.282-312). New York: Garland Publishing, 1986 Physiological research is reviewed indicating that transcendental consciousness is a unique fourth major state of consciousness.
A20: Mental Potential | B20: Psychological CP Vol5 Pg3411 | C20: Development of Personality | D20: TC+ | F20: 1990 | G20: s | H20: Alexander CN, Davies JL, Dixon CA, Dillbeck MC, Oetzel RM, Drucker SM, Muehlman JM, Orme-Johnson DW. Growth of higher stages of consciousness: Maharishi’s Vedic psychology of human development. In CN Alexander, EJ Langer (eds), Higher Stages of Human Development: Perspectives on Adult Growth (pp.286-341). New York: Oxford University Press, 1990 The authors describe how theory and research in Maharishi’s Vedic Psychology fulfills the quest of psychology to understand and promote the full range of human development. Are proposed postformal stages truly qualitatively distinct from formal operations? Kramer (1983) asserts that genuine post-formal stages should satisfy three criteria of structural change: (I) greater abstraction of thought than in formal operations, (2) hierarchical integration of formal operations, and (3) broader equilibrium (see Piaget, 197la; Inhelder & Piaget, 1958). We will briefly examine proposed post-formal theories in this volume in relation to these criteria. Many of the authors who delineate postformal stages agree about several of their main features, and it has been suggested (e.g., by Richards & Commons) that the alignment among these descriptions may reflect the universality of the underlying stages being described. However, it has yet to be demonstrated that an individual meeting developmental criteria for one proposed stage necessarily expresses the characteristics integral to the corresponding stages of the other theorists. For example, does capacity to reason about systems of systems on the level of abstract thought necessarily coexist with greater affective and self integration? This issue, as do many others raised by the expansive theorizing contained in this volume, promises to stimulate new directions and levels of developmental research. One summary generalization can be safely made: Virtually all contributors agree that an understanding of adolescent development does not provide an adequate base for comprehending the breadth, depth, and richness of potential development in adulthood. Further conceptual clarification and research on the nature of development beyond formal operations should lead to significant revision of our understanding of the possibilities for fully "mature" forms of human growth. Ultimately, how we conceive of the endpoint of development will not only influence the direction of our research agendas but either restrict or encourage our own personal development as well.
A21: Mental Potential | B21: Psychological | C21: Development of Personality | D21: Adult Growth | F21: 1990 | G21: s | H21: Alexander CN, Drucker SM, Langer EJ. Major issues in the exploration of adult growth. In CN Alexander, EJ Langer (eds), Higher Stages of Human Development: Perspectives on Adult Growth (pp.3-32). New York: Oxford University Press, 1990 What are the highest possible forms of human development? One's conception of the endpoint of development is fundamental, for it contains one's assumptions about the direction, possibilities, and dynamics of human growth. Moreover, all prior developmental stages will be viewed as progressive approximations of this goal. Contributors to this volume were asked to address this basic issue of end point. Answering this question generally requires examination of three related issues: Does development toward the endpoint proceed through qualitatively distinct stages? What mechanisms underlie this development? What major areas get developed (e.g., cognition and affect), and how do they interrelate? Based on recent theory and research, the chapters in this book provide expanded perspectives on these important issues.
A22: Mental Potential | B22: Psychological | C22: Education | D22: Management | F22: 1990 | G22: s | H22: Alexander CN, Heaton DP, Chandler HM. Promoting adult psychological development: implications for management education. Human Resource Management 1990 2:133-137 This paper addresses the critical question of what management education can do to develop the personal characteristics needed to fulfill the demand for managers. We argue that 1) psychological development underlies performance of the tasks of management, and 2)psychological development can be facilitated by appropriate technologies; therefore, 3) such a technology can be employed to develop managers and beyond. longitudinal studies of ego developmental technology, the Transcendental Meditation technique experienced unprecedented unfreezing of psychological development in adulthood. Further application of this technology may facilitate the development of managers for the demands of the twenty-first century.
A23: Mental Potential | B23: Psychological CP Vol6 Pg4325 | C23: Development of Personality | D23: TC+ | F23: 1994 | G23: s | H23: Alexander CN, Heaton DP, Chandler HM. Advanced human development in the Vedic Psychology of Maharishi Mahesh Yogi: theory and research. In ME Miller, SR Cook-Greuter (eds), Transcendence and Mature Thought in Adulthood: The Further Reaches of Adult Development (pp.39-70). Lanham, Maryland: Rowman & Littlefield, 1994 The authors describe the development of higher states of consciousness as brought to light by Maharishi Mahesh Yogi in his Vedic Psychology, and contrast this to contemporary themes of cognitive or self-development. The authors then review research demonstrating uniquely high scores on self-development among advanced practitioners in Maharishi’s Transcendental Meditation and TM-Sidhi Program.
A24: Mental Potential | B24: Psychological | C24: Education | D24: Word of Wisdom | F24: 2005 | G24: s | H24: Alexander CN, Kurth SC, Travis F, Alexander VK. Effect of practice of the children’s Transcendental Meditation technique on cognitive stage development: acquisition and consolidation of conservation. Journal of Social Behavior and Personality 2005 17(1):21-46 The results of this study on cognitive stage development in children practicing the Maharishi Word of Wisdom technique are striking. These findings suggest that practice of the Word of Wisdom technique may accelerate the rate of acquisition and especially consolidation of conservation in childhood. The transition period in the mastery of consolidation of conservation - horizontal decalage - was substantially reduced in these children. The results of this study clearly indicate that children’s practice of the Word of Wisdom technique is positively related to performance on a series of cognitive development tasks measuring conservation. All three experimental hypotheses were supported. First, the children practicing the Word of Wisdom technique, appeared to begin acquisition of conservations skills at an earlier age than controls. Second, a significantly greater proportion of the Word of Wisdom group exhibited full consolidation of conservation, as indicated by complete mastery of the conservation series. Finally, significantly fewer of the Word of Wisdom children displayed horizontal decalage as indicated by a transitional score on the conservation series. The performance of the children practicing the Word of Wisdom technique suggests phase transitions between stages rather than prolonged temporal displacement. A striking implication of this accelerated consolidation finding is that optimization of the natural growth process in childhood through the practice of the World of Wisdom technique may result in a substantial foreshortening, and in some cases, possible elimination of the developmental “irregularity” of horizontal decalage. Given that virtually all of the children who were practicing the Word of Wisdom technique were fully conserving by age 5.08 years and that complete conservation does not typically occur until 11 or 12 years of age, the strongest possible interpretation of these data would suggest that practice of the Word of Wisdom technique may accelerate consolidation of conservation by as much as 5 to 7 years in comparison to the larger population. This cross sectional study examined cognitive stage development in 47 children practicing the Word of Wisdom technique and in 47 matched controls.
A25: Mental Potential | B25: Psychological | C25: Development of Personality | D25: TC+ | F25: 1990 | G25: s | H25: Alexander CN, Langer EJ (eds). Higher Stages of Human Development: Perspectives on Adult Growth. New York: Oxford University Press, 1990 The authors describe how theory and research in Maharishi’s Vedic Psychology fulfills the quest of psychology to understand and promote the full range of human development. This research provides striking evidence that Maharishi’s Transcendental Meditation program facilitates development across four major periods of development. These findings challenge a widely held tenet in developmental psychology that quality of direct interaction with the external physical or social environment is necessarily the critical factor influencing cognitive growth. In these studies, neither external enrichment of the environment, nor training with test-related materials or even with related concepts was employed. Instead, substantial change resulted from systematically turning attention inward to intrinsically deeper levels of mind and, ultimately, pure consciousness at their source. Regardless of the subject’s initial developmental level (e.g., sometimes quite low in the prison samples: Alexander, 1982) rate of development was rapidly accelerated through experiences of pure consciousness during the TM technique. Based upon these results the authors conclude that the process of transcending through the TM program facilitates development across periods of development commonly identified by contemporary psychology, and extends this process of growth to the higher states of consciousness described by Maharishi’s Vedic Psychology. They propose that were this developmental technology widely introduced at the earliest appropriate age, development would not freeze prematurely and growth to full enlightenment would appear as the inevitable consequence of normal human development.
A26: Health | B26: Physiological CPVol 6 Pg3840 | C26: Health: Longevity | D26: Aging; Reduced Blood Pressure, Improved Cognitive Functioning and Increased Longevity | E26: RCT | F26: 1989 | G26: s | H26: Alexander CN, Langer EJ, Newman RI, Chandler HM, Davies JL. Transcendental Meditation, mindfulness, and longevity: an experimental study with the elderly. Journal of Personality and Social Psychology 1989 57(6):950-964 A meticulously controlled randomized study at Harvard University found that elderly individuals who learned the Transcendental Meditation technique showed significantly greater improvements in a variety of age-related aspects of physical and mental health and well-being than subjects taught other techniques or a no treatment control group. In particular, those who learned a relaxation procedure that attempted to imitate Transcendental Meditation technique showed no improvement on any measure. A clear majority of subjects practicing the TM technique rated their technique as particularly useful and easy to practice in contrast to lower rates for the other techniques. Most strikingly, after three years, all those who had learned the TM technique were still living in contrast to significantly lower survival rates for the other three groups and for the remaining inhabitants of the other institutions where the study was conducted. Benefits for the Elderly Demonstrating Reversal of Aging: Increased Longevity (Higher Survival Rate); Reduction of Systolic Blood Pressure to More Ideal Levels; Improved Mental Health (Improvements on Nursesi Mental Health Ratings); Increased Cognitive Flexibility (Verbal Task); Increased Learning Ability (Paired Associate Learning Task); Improvements in Self-Reported Measures of Behavioral Flexibility and Aging (Greater Ability to Cope with Inconvenience, Reduced Feelings of Being Old); Greater Sense of Well-Being (Feeling Better and More Relaxed After Transcendental Meditation; Feeling Better During Transcendental Meditation; High Interest in Transcendental Meditation; and High Ratings of the Value of Transcendental Meditation.)
A27: Social Behavior | B27: Sociological CP Vol 7 Pg4900 | C27: Rehabilitation | D27: TM in Corrections Reduced Schizophrenic Symptoms, Reduced Aggression, Decreased Anxiety | F27: 2003 | G27: s | H27: Alexander CN, Orme-Johnson DW. Walpole study of the Transcendental Meditation program in maximum security prisoners II: longitudinal study of development and psychopathology. Journal of Offender Rehabilitation 2003 36(1-4):127-160 Prison inmates in Massachusetts, USA, who learned the Transcendental Meditation program and practiced regularly over a 15-month period, in contrast to control inmates, showed significantly increased ego development, decreased aggression, reduced schizophrenic symptoms, and increased frequency of experiences of higher consciousness in comparison to members of several control groups. 271 maximum-security prisoners who were participating in either the Transcendental Meditation (TM) program, counseling, drug rehabilitation, or faith based groups. Only regular participants in the TM program changed significantly. TM subjects showed significant reductions in aggression (p < .05), especially those who meditated at least twice a week (p < .005). In addition, they showed reduced schizophrenic symptoms (p < .05), decreased trait-anxiety (p < .10, trend), and increased frequency of postconceptual experience of higher states of consciousness (p < .01)
A28: Social Behavior | B28: Sociological CP Vol 7 Pg4923 | C28: Rehabilitation | D28: TM in Corrections Reduced Recidivism | F28: 2003 | G28: s | H28: Alexander CN, Rainforth MV, Frank PR, Grant JD, Von Stade C. Walpole study of the Transcendental Meditation program in maximum security prisoners III: reduced recidivism. Journal of Offender Rehabilitation 2003 36(1-4):161-180 Prison inmates in Massachusetts, USA, who learned the Transcendental Meditation program while incarcerated showed significantly less return to prison for 30 days or longer in contrast to control groups from the same prison, as well as in a significantly lower rate of reincarceration due to new arrests. Inmates who practiced the TM Technique experienced a reduction in recidivism of 33%, which was statistically significant (p = .042). Separate comparisons showed that the TM group also had lower re-incarceration rates than each of the four other programs, with proportionate reductions in recidivism ranging from 29% to 42% (p = .007 to .073). In addition, the TM group compared to all non-meditating subjects had a lower rate of re-incarceration due to new convictions (47% lower, proportionately; p = .045) and a 27% proportionately lower rate of re-incarceration/warrant for arrest (p = .069). The pattern of reduced recidivism for TM program members was maintained in multiple regression analyses, controlling for background and release variables (e.g., parole vs. full discharge, institution of release, drug history). These findings are consistent with the proposition that the reduced psychopathology and accelerated psychological development resulting from the TM program are responsible for reductions in criminal behavior. In this study, a group who had learned the TM program (N = 53) was compared to a control group (N = 233) of inmates who did not practice the TM technique.
A29: Mental Potential | B29: Psychological CP Vol6 Pg3966 | C29: Development of Personality | D29: Self-Actualization | E29: Meta | F29: 1991 | G29: s | H29: Alexander CN, Rainforth MV, Gelderloos P. Transcendental Meditation, self-actualization, and psychological health: a conceptual overview and statistical meta-analysis. Journal of Social Behavior and Personality 1991 6(5):189-247 This meta-analysis of all research on the effects of the TM program on self-actualization, in comparison to other techniques found that the Transcendental Meditation program had 3 times the effect size of other procedures in enhancing self actualization and it’s other components (emotional maturity, integrated perspective on self and world, and resilient sense of self.) The Transcendental Meditation program was also found to lead to significant improvements on each of the twelve scales of the most common test of self-actualization. In a statistical review of 42 independent research results the TM program was found to be three times as effective as other meditation and relaxation procedures in increasing self-actualization an overall measure of positive mental health and personal development. Further analysis revealed that the technique is exceptionally effective in developing three independent components of this dimension: emotional maturity, a resilient sense of self, and a positive integrated perspective on ourselves and the world Increased Self Actualization through Transcendental Meditation in Contrast to other Procedures as Demonstrated by Meta-Analysis; Improvement in the Measured Components of Self-Actualization: Increased Time Competence (Ability to Live in the Present; Ability to Connect Past, Present, and Future Meaningfully); Increased Inner-Directedness (Independence; Self-Supportiveness); Increase Self-Actualizing Value (Holding Values of Self-Actualizing People); Increased Existentiality (Flexibility in Application of Values); Increased Spontaneity; Increased Self-Regard; Increased Self-Acceptance; Increased Nature of Man Constructive (See Man as Essentially Good); Increased Synergy (Sees Opposites of Life as Meaningfully Related); Increased Acceptance of Feelings; Increased Capacity for Intimate Contact (Warm Interpersonal Relationships); Increased Emotional Maturity; Increased Integrative Perspective on Self and World; Increased Resilient Sense of Self
A30: Health | B30: Physiological Review CPVol 6 Pg 4255 | C30: Cardiovascular Health Rehabilitation Affective, Development of Personality | D30: Comparing Techniques Reviews 4 Meta-Analyses | F30: 1994 | G30: s | H30: Alexander CN, Robinson P, Orme-Johnson DW, Schneider RH, Walton KG. The effects of Transcendental Meditation compared to other methods of relaxation in reducing risk factors, morbidity, and mortality. Homeostasis 1994 352:243-264 This paper reviews four meta-analyses that show the superiority of the Transcendental Meditation program compared to other techniques in producing deep rest, decreasing anxiety, increasing self-actualization, and decreasing substance abuse (cigarettes, drugs, alcohol). It also reviews individual well controlled studies on the beneficial effects of this technique on hypertension, mortality, medical care, and medical expenses, and discusses physiological mechanisms for these effects.
A31: Social Behavior | B31: Sociological CPVol 6Pg 4013 | C31: Rehabilitation | D31: Reduced Substance Abuse (Alcohol, Drugs and Cigarettes) | E31: Meta | F31: 1994 | G31: s | H31: Alexander CN, Robinson P, Rainforth MV. Treating and preventing alcohol, nicotine, and drug abuse through Transcendental Meditation: a review and statistical meta-analysis. Alcoholism Treatment Quarterly 1994 11(1/2):13-87 This paper presents a meta-analysis of the Transcendental Meditation program, indicating that individuals who learn this program show a significantly greater reduction in use of illegal drugs, alcohol and cigarettes than do individuals who participate in programs of relaxation, prevention or treatment. The results also showed that abstinence from illegal drugs, alcohol and cigarettes, was maintained or even increased over a long period of time among those who participated in the TM program, in contrast to high relapse rates for standard treatment programs. The meta-analysis also indicated that individuals with substance abuse problems who learned the TM program, showed significantly improved psychological health in comparison to controls. This meta-analysis of 155 studies found that the TM program was significantly more effective in reducing alcohol consumption (d=0.55) than relaxation techniques, counseling, peer pressure and DUI programs, (ds ranged from 0.07 to 0.33). In addition, a statistical meta-analysis summarizing 19 studies on the effects of the TM program found the technique produced substantial and highly significant reductions in alcohol, cigarettes and illegal drug use, with larger effects than other treatments, including standard therapies and other techniques of meditation and relaxation. Over an 18-24 month period, abstinence ranged from 51% to 89% for the TM program compared to 21% for good conventional substance abuse programs. Results of Integrative Meta-Analysis: Significantly Greater Reduction in Use of Illegal Drugs, Alcohol, and Cigarettes than Programs of Relaxation, Prevention, or Treatment; Abstinence from Illegal Drugs, Alcohol, and Cigarettes Maintained or Increased over Long Term (Relapse Prevention); Improved Psychological Health (Reduced Negative Qualities, Reduced Anxiety, Improved Positive Qualities) Among Those with Substance Abuse Problems in Comparison to Controls. Decades of efforts in the treatment of substance abuse have failed to yield a comprehensive treatment strategy that successfully addresses the multidimensional nature of chemical addiction. The current paper proposes that the Transcendental Meditation (TM) program provides a holistic, natural, and effective approach that positively impacts a constellation of factors-social, environmental, physiological, psychological, and spiritual-that influence addictive behavior. TM’s effects on smoking, drinking and use of illicit drugs tend to increase over time, suggesting a cumulative effect of regular TM practice. In contrast, it is known that success rates for standard drug treatments fall off substantially over time. For alcohol abuse, TM produced a significantly greater effect than: (1) education programs designed to foster resistance to peer-pressure; (2) prevention education programs designed to enhance self-esteem and knowledge of drug consequences (3) the average of a wide range of DUI treatment programs such as AA and therapeutic probation programs and (4) the average of other relaxation treatment programs (including biofeedback, muscle relaxation, stress-management training, and other forms of meditation). For tobacco smoking, TM produced significantly greater effects than: (1) drug prevention education programs; (2) counseling programs for smoking cessation (3) bibliotherapy; (4) pharmacological treatments for nicotine addiction (including nicotine replacement programs and clonodine therapy); and (5) “unconventional” treatment (including acupuncture, hypnosis, sensory deprivation, etc.). For illicit drugs (cannabis, hallucinogens and narcotics), TM produced significantly greater effects than: (1) preventative education programs combining peer-pressure; and (2) preventative education programs fostering self-esteem and knowledge about drugs.
A32: Mental Potential | B32: Psychological | C32: Affective | D32: Relaxation | F32: 1993 | H32: Alexander CN, Sands D. Meditation and relaxation. In FN McGill (ed.), McGill’s Survey of the Social Sciences: Psychology (pp.1499-1505). Pasadena, California: Salem Press, 1993
A33: Health | B33: Physiological | C33: Cardiovascular | D33: Reduced Hypertension and Aging/Gender | E33: RCT | F33: 1996 | G33: s | H33: Alexander CN, Schneider RH, Staggers F, Sheppard W, Clayborne BM, Rainforth MV, Salerno J, Kondwani K, Smith S, Walton K, Egan B. Trial of stress reduction for hypertension in older African Americans: II. Sex and risk subgroup analysis. Hypertension 1996 28(2):228-237 More Ideal Levels of Blood Pressure in Hypertensive Subjects who Learned the Transcendental Meditation Programme: Reduction of HIgh Systolic and Diastolic Blood Pressure Found for both Men and Women, and both High and Low Psychosocial Stress Subjects: Reduction of High Systolic and Diastolic Blood Pressure Irrespective of Score on Five other Measures of Risk for High Blood Pressure, Obesity, Alcohol Use, Physical Inactivity, Dietary Sodium-Potassium Intake and Index of all Risk Factors Combined.
A34: Health & Social Behavior | B34: Sociological CPVol6 Pg 4056 | C34: Productivity and Quality of Life Dev of Personality | D34: Decreased Insomnia Workplace Less Stress, Reduced Cigarettes and Hard Liquor | F34: 1993 | G34: s | H34: Alexander CN, Swanson GC, Rainforth MV, Carlisle TW, Todd CC, Oates RM. Effects of the Transcendental Meditation program on stress reduction, health, and employee development: a prospective study in two occupational settings. Anxiety, Stress, and Coping 1993 6:245-262 This research study found that executives and employees who learned and regularly practiced theTranscendental Meditation program, in contrast to other employees from the same worksites, showed increased employee effectiveness, increased job satisfaction, improved personal and work relationships, reduced job worry and tension, reduced trait anxiety, decreased insomnia and decreased fatigue, reduced cigarette and hard liquor use, improved health and greater calm (lower skin conductance during task performance. The groups of participants in the Transcendental Meditation program also showed, in contrast to controls, improvement on three components found to underlie each of these measures, - increased occupational coherence, increased physiological settledness, and increased satisfaction with professional and personal life. This study examined health, stress and employee development in two settings in the automotive industry; a large manufacturing plant of a Fortune 100 company and a small sales distribution company. Employees who learned the TM technique showed significantly greater improvements on a wide variety of measures, including: reduced physiological arousal; decreases in anxiety, job tension, insomnia and fatigue; reduced consumption of cigarettes and hard liquor; and improved general health.
A35: Social Behavior | B35: Sociological CP Vol 7 Pg4879 | C35: Rehabilitation | D35: TM in Corrections | F35: 2003 | G35: s | H35: Alexander CN, Walton KG, Goodman R. Walpole study of the Transcendental Meditation program in maximum security prisoners I: cross-sectional differences in development and psychopathology. Journal of Offender Rehabilitation 2003 36(1-4):97-126 Prison inmates in Massachusetts, USA, who had previously learned the Transcendental Meditation program, in contrast to control inmates, were found to display significantly higher psychological development and development of consciousness, and significnatly lower psychopathology. Significant improvements in the TM group including improved ego development (p<.0005), improved interpersonal relationships (p<.05), reduced psychopathic deviation (p<.01), reduced anxiety (p<.05), reduced aggression (p<.05), reduced tension (p<.05), and reduced introversion (p<.05)These outcomes, identify the TM program as an effective tool for promoting the psychological health and personal maturation necessary for lasting rehabilitation of maximum-security inmates.
A36: Social Behavior | B36: Sociological | C36: Rehabilitation | D36: TM in Corrections | F36: 2003 | G36: s | H36: Alexander CN, Walton KG, Orme-Johnson DW, Goodman RS, Pallone NJ (eds). Transcendental Meditation in Criminal Rehabilitation and Crime Prevention. Binghamton, New York: Haworth Press, 2003 Benefits of The TM Technique experienced in 4 prison systems as well as, wide-ranging benefits of the TM program experienced by probationers that had committed offenses ranging from drunk driving to manslaughter. A comprehensive summary describing risk factors associated with the likelihood of criminal behavior and substance misuse and summarizing research indicating how the TM program successfully addresses many of these factors. A macroscopic view of the role of the TM program in criminal rehabilitation.
A37: Health | B37: Physiological | C37: Efficiency & Stability | D37: Respiratory Changes | F37: 1970 | G37: s | H37: Allison J. Respiratory changes during Transcendental Meditation. Lancet 1970 7651:833 Breath rate decreased during the practice of the TM technique, indicating a more relaxed and rested state.
A38: Health | B38: Physiological | C38: Cardiovascular | D38: Reduced Hypertension | E38: Meta | F38: 2008 | G38: s | H38: Anderson JW, Liu C, Kryscio RJ. Blood pressure response to Transcendental Meditation: a meta-analysis. American Journal of Hypertension 2008 21(3):310-316 According to a definitive new meta-analysis of previous studies on stress reduction programs and high blood pressure, the Transcendental Meditation technique was found to produce a statistically significant reduction in high blood pressure—an effect not found with other forms of relaxation, meditation, biofeedback or stress management. Blood pressure dropped significantly in all groups practicing TM compared to the controls. The reduction in blood pressure was an average of 5 points on the systolic and 3 points on the diastolic readings. These results are not only statistically significant, they are clinically significant. These results could be expected to result in 15 - 20% less cardiovascular disease. Jim Anderson and colleagues from the University of Kentucky pooled data from nine published well controlled studies that involved a total of 711 people. Subjects ranged in age from adolescents (15-18 years) to seniors (M age 81.3 + or - 9.8 years) and included normotensive, prehypertensive and hypertensive individuals.
A39: Social Behavior | B39: Sociological | C39: Rehabilitation | D39: TM in Corrections | F39: 2003 | G39: s | H39: Anklesaria FK, King MS. The Enlightened Sentencing Project: a judicial innovation. Journal of Offender Rehabilitation 2003 36(1-4):35-46 Probationers “sentenced” to The TM Technique report less anger, decreased substance abuse,. Judges report the probationers practicing TM have greater self-esteem and self-control, positive social attitude, increased ability to secure employment. Starting in 1996, Judge David C. Mason, a Missouri circuit court judge began sentencing probationers (offenses from drunk driving to manslaughter) to learn The TM Technique and to attend classes on the technique. As of the publication of this study in 2003, 6 judges in Missouri have sentenced 100 probationers to The TM Program. Probation Officers in Missouri are also experiencing the wide range of benefits of the TM Program. Through the creative use of existing laws, the Enlightened Sentencing Project is an example of successful judicial innovation to meet a social need.
A40: Social Behavior | B40: Sociological | C40: Rehabilitation | D40: TM in Corrections | F40: 2003 | G40: s | H40: Anklesaria FK, King MS. The Transcendental Meditation program in the Senegalese penitentiary system. Journal of Offender Rehabilitation 2003 36(1-4):303-318 Between 1987 and 1989, more than 11,000 inmates and 900 correctional officers and prison administrators in 31 of the 34 prisons in the West African nation of Senegal were instructed in the Transcendental Meditation1 program. Rule infractions decreased, medical expenses went down 70%, and recidivism dropped from 90% in the pre-meditation period to less than 3% after the program was established.
A41: Health | B41: Physiological | C41: Motor & Perceptual | D41: Reaction Time | F41: 1974 | G41: s | H41: Appelle S, Oswald LE. Simple reaction time as a function of alertness and prior mental activity. Perceptual and Motor Skills 1974 38(3):1263-1268 Subjects practicing the Transcendental Meditation technique were found to have faster reactions before and after a session of the technique, compared with other subjects before and after either rest or a simple task.
...

Sheet Sleep Studies
A1: TM Research on Sleep / Insomnia
A2: Studies from Sheet1 where sleep or insomnia is an explicit outcome. Rows link back to Sheet1.
A4: Source Row | B4: Year | C4: Design | D4: Sleep-Related Results | E4: General Topic | F4: Specialty Area | G4: Full Citation & Abstract
A5: 435 | B5: ='All Research'!F435 -> 2021 | C5: =IF('All Research'!E435="","Observational",'All Research'!E435) -> RCT | D5: ='All Research'!D435 -> Reduced Emotional Distress, Anger, Fatigue Improved Academic Achievement, Quality of Sleep, Well Being | E5: ='All Research'!A435 -> Health & Mental Potential | F5: ='All Research'!C435 -> Affective | G5: ='All Research'!H435 -> Valosek L, Nidich S, Grant J, Peterson M, Nidich R. Effect of meditation on psychological stress and academic achievement in high school students: a randomized controlled study. Education 2021 141(4):192-200 The results of this randomized controlled study of ninth-grade students indicated significant reductions in the meditation group compared to silent reading controls in overall emotional distress, anger, and fatigue, and improvement in English language arts academic achievement and quality of sleep. These findings indicate the value of implementing TM to improve emotional wellbeing and academic performance in high school students. Analysis of covariance indicated that practice of meditation compared to controls significantly decreased psychological distress, as measured by SDQ emotional symptoms (F(1, 79)=4.90, p=.030), and anger (F(1, 80)=5.11, p=.027). The reduction in anxiety was in the expected direction but was not statistically significant F(1, 78)=0.46, p=.499).There was a significant improvement in the quality of sleep in the meditation group compared to controls (F(1, 79)=6.40, p=.013) and a marginally significant reduction in fatigue F(1, 80)=3.08, p=.082. (See Table 2.) Improvement was found in English Language Arts (ELA) academic achievement from prior year for the meditation group compared to controls (F(1, 66)=3.18, p=.079). Subgroup analysis of students who were below proficiency at baseline (n=37) indicated that 69% of the meditation students (11 out of 16) improved at least one performance level at post test compared to 33% of the control students (7 out of 21; [chi square]=4.56, p=.033). Change in attendance was also in the positive direction for the meditation group but did not reach statistical significance compared to controls (F(1, 81)=1.96, p=.166). Results of this study in ninth-grade students indicated significant reductions in psychological stress factors, decreased fatigue, improved quality of sleep, and increased academic achievement. This study builds upon previous research with school students (Nidich et al., 2011; Wendt et al., 2015; Valosek et 2018) while employing a randomized controlled design. The results are consistent with a large randomized study with college students, showing reduced psychological distress factors in those practicing TM compared to wait-list controls.
A6: 51 | B6: ='All Research'!F51 -> 2021 | C6: Pilot | D6: ='All Research'!D51 -> Reduced Insomnia, Anxiety Depression,Stress | E6: ='All Research'!A51 -> Health | F6: ='All Research'!C51 -> Affective | G6: ='All Research'!H51 -> Azizoddin DR, Kvaternik N, Beck M, Zhou G, Hasdianda MA, Jones N, Johnsky L, Im D, Chai PR, Boyer, EW. Heal the Healers: a pilot study evaluating the feasibility, acceptability, and exploratory efficacy of a Transcendental Meditation intervention for emergency clinicians during the coronavirus disease 2019 pandemic. Journal of the American College of Emergency Physicians Open 2021 2(6):e12619.doi.org/10.1002/emp2.12619 Abstract Objective: Emergency clinicians face elevated rates of burnout that result in poor outcomes for clinicians, patients, and health systems. The objective of this single-arm pilot study was to evaluate the feasibility of a Transcendental Meditation (TM) intervention for emergency clinicians during the coronavirus disease 2019 (COVID-19) pandemic and to explore the potential effectiveness in improving burnout, sleep, and psychological health. Methods: Emergency clinicians (physicians, nurses, and physician-assistants) from 2 urban hospitals were recruited to participate in TM instruction (8 individual or group in-person and remote sessions) for 3 months. Session attendance was the primary feasibility outcome (prespecified as attending 6/8 sessions), and burnout was the primary clinical outcome. Participant-reported measures of feasibility and validated measures of burnout, depression, anxiety, sleep disturbance, and stress were collected at baseline and the 1-month and 3-month follow-ups. Descriptive statistics and linear mixed effects models were used. Results: Of the 14 physicians (46%), 7 nurses (22%), and 10 physician-assistants (32%) who participated, 61% were female (n = 19/32). TM training and at-home meditation practice was feasible for clinicians as 90.6% (n = 29/32) attended 6/8 training sessions and 80.6% self-reported meditating at least once a day on average.Participants demonstrated significant reductions in burnout (P < .05; effect sizes, Cohen’s d = 0.43–0.45) and in symptoms of depression, anxiety, stress, and sleep disturbance (P values < .001; Cohen’s d = 0.70–0.87).
A7: 289 | B7: ='All Research'!F289 -> 2023 | C7: =IF('All Research'!E289="","Observational",'All Research'!E289) -> Observational | D7: ='All Research'!D289 -> Increased Clarity, Focus, Resilience, Energy, Stamina, Efficiency, Memory, Learning, Recall, Quality Sleep, Productive Time, Reduced Anxiety, | E7: ='All Research'!A289 -> Mental Potential Health | F7: ='All Research'!C289 -> Affective & Cognitive | G7: ='All Research'!H289 -> Nader T, Carroll RJ, Travis FW, Bray JB, Gruener G, Rothenberg S, Brown DH, Brown CL. A larger lens: medical students benefit from consciousness-based self-care. In ﻿AK Maheshwari (ed), Consciousness-Based Leadership and Management, Volume 2, Chapter 2 (pp 13-46), 2023. Palgrave Studies in Workplace Spirituality and Fulfillment. doi.org/10.1007/978-3-031-05839-4_2 Summary of Findings Three major benefits of regular TM practice were observed in these data: Students found that their most pressing needs—stress and anxiety reduction—were relieved with the TM technique. Students reported multiple positive benefits relating to many facets of their health and well-being, including: Greater mental clarity and improved focus Increased resilience, energy, stamina and efficiency Increased confidence, sense of control and adaptability Increased emotional stability, compassion, and empathy Improved memory, recall, learning and ability to synthesize Improved sleep and relief from physical symptoms of anxiety Improved relationships and teamwork With regular practice of the TM technique, the students gained additional productive time daily.
A8: 34 | B8: ='All Research'!F34 -> 1993 | C8: =IF('All Research'!E34="","Observational",'All Research'!E34) -> Observational | D8: ='All Research'!D34 -> Decreased Insomnia Workplace Less Stress, Reduced Cigarettes and Hard Liquor | E8: ='All Research'!A34 -> Health & Social Behavior | F8: ='All Research'!C34 -> Productivity and Quality of Life Dev of Personality | G8: ='All Research'!H34 -> Alexander CN, Swanson GC, Rainforth MV, Carlisle TW, Todd CC, Oates RM. Effects of the Transcendental Meditation program on stress reduction, health, and employee development: a prospective study in two occupational settings. Anxiety, Stress, and Coping 1993 6:245-262 This research study found that executives and employees who learned and regularly practiced theTranscendental Meditation program, in contrast to other employees from the same worksites, showed increased employee effectiveness, increased job satisfaction, improved personal and work relationships, reduced job worry and tension, reduced trait anxiety, decreased insomnia and decreased fatigue, reduced cigarette and hard liquor use, improved health and greater calm (lower skin conductance during task performance. The groups of participants in the Transcendental Meditation program also showed, in contrast to controls, improvement on three components found to underlie each of these measures, - increased occupational coherence, increased physiological settledness, and increased satisfaction with professional and personal life. This study examined health, stress and employee development in two settings in the automotive industry; a large manufacturing plant of a Fortune 100 company and a small sales distribution company. Employees who learned the TM technique showed significantly greater improvements on a wide variety of measures, including: reduced physiological arousal; decreases in anxiety, job tension, insomnia and fatigue; reduced consumption of cigarettes and hard liquor; and improved general health.
A9: 201 | B9: ='All Research'!F201 -> 1990 | C9: =IF('All Research'!E201="","Observational",'All Research'!E201) -> Observational | D9: ='All Research'!D201 -> Decreased Insomnia, Decreased Cigarettes, Increased Health of Industrial Workers | E9: ='All Research'!A201 -> Health | F9: ='All Research'!C201 -> Productivity and Quality of Life | G9: ='All Research'!H201 -> Haratani T, Hemmi T. Effects of Transcendental Meditation on health behavior of industrial workers. Japanese Journal of Public Health 1990 37:729 Industrial workers who learned the Transcendental Meditation program, in contrast to control employees, showed improved sleep quality, and decreased cigarette consumption. This study was conducted to assess the effect of the Transcendental Meditation program on worker’s health and behavior. Surveys were conducted before and after the introduction of the TM program. 427 TM participants and 308 controls who did not begin the practice in terms of health and behavior. The group who learned the TM program showed reduced time to fall asleep, less awakening during sleep, decrease in habitual smoking and fewer cigarettes smoked.
A10: 202 | B10: ='All Research'!F202 -> 1990 | C10: =IF('All Research'!E202="","Observational",'All Research'!E202) -> Observational | D10: ='All Research'!D202 -> Decreased Insomnia, Decreased Cigarettes, Increased Mental Health of Industrial Workers | E10: ='All Research'!A202 -> Health Social Behavior | F10: ='All Research'!C202 -> Productivity and Quality of Life | G10: ='All Research'!H202 -> Haratani T, Hemmi T. Effects of Transcendental Meditation on mental health of industrial workers. Japanese Journal of Industrial Health 1990 32:656 Takashi Haratani This was a five month study conducted by the researchers at Japan’s National Institute of Industrial Health. (A branch of the Japanese Ministry of Labor) industrial employees practicing the TM technique showed increased emotional stability, reduced anxiety, decreased tendency to neurosis and reduced insomnia and smoking compared to controls. Improvement in General Physical and Mental Well-Being in Industrial Workers: Decreased Physical Complaints; Decreased Impulsive Tendency; Reduced Emotional Instability. Overall, employees practicing TM improved significantly on 10 out of 14 mental health scales, whereas controls improved on only one.
A11: 15 | B11: ='All Research'!F15 -> 1978 | C11: =IF('All Research'!E15="","Observational",'All Research'!E15) -> Observational | D11: ='All Research'!D15 -> Reduced Insomnia TM in Corrections | E11: ='All Research'!A15 -> Social Behavior | F11: ='All Research'!C15 -> Rehabilitation | G11: ='All Research'!H15 -> Abrams AI, Siegel LM. The Transcendental Meditation program and rehabilitation at Folsom State Prison: a cross-validation study. Criminal Justice and Behavior 1978 5(1):3-20 The Transcendental Meditation program in a maximum security prison was studied via cross-validation design. Significant differences were found between the Transcendental Meditation and control groups across all the inventories, indicating reduction in anxiety, neuroticism, hostility, insomnia, fewer behavior infractions, decreased resentment; decreased negativism decreased irritability; improved sleep patterns (decreased time to fall asleep, decreased awakenings per night, improved quality of sleep).
A12: 271 | B12: ='All Research'!F271 -> 1977 | C12: =IF('All Research'!E271="","Observational",'All Research'!E271) -> Observational | D12: ='All Research'!D271 -> Decreased Insomnia, Reduced Use of Tranquilizers, Reduced Stress | E12: ='All Research'!A271 -> Mental Potential & Health | F12: ='All Research'!C271 -> Development of Personality | G12: ='All Research'!H271 -> Ljunggren G. The influence of Transcendental Meditation on neuroticism, use of drugs and insomnia. Lakartidningen 1977 74(47):4212-4214 Improvements in neuroticism and insomnia, and reduced use of tranquilizers were found to result from three months’ practice of the Transcendental Meditation technique. These findings indicate a relief from stress and increased psychological balance.

Sheet Alle Forschung
A1: MIT FREUNDLICHER GENEHMIGUNG DER GLOBAL MOTHER DIVINE ORGANIZATION® | H1: Forschungspublikationen zu
A2: Anfragen bitte per E-Mail an: tmresearchspreadsheet@tm-women.org | H2: Transzendentale Meditation® und TM-Sidhi-Programme®
H3: Bibliografie 1970–2026∗
H4: Diese Tabelle (Datenbank), erstellt von Jean Tobin von der Global Mother Divine Organization, fasst Zusammenfassungen, Abstracts und Daten zu Studiendesign und Ergebnissen von 485 Arbeiten zusammen, die in begutachteten Fachzeitschriften oder anderen unabhängigen, redaktionell betreuten wissenschaftlichen Publikationen veröffentlicht wurden. Die meisten dieser Arbeiten berichten über Originalstudien oder Forschungsübersichten; eine kleine Anzahl liefert wichtige Kommentare oder Klarstellungen zu bestimmten Studien, einschließlich Antworten auf Kritiken. Einige wenige Studien untersuchen einen umfassenden multimodalen Gesundheitsansatz, der die Transzendentale Meditation® einschließt. Transcendental Meditation®, TM® und TM-Sidhi® sind geschützte Marken und werden in den USA unter Lizenz oder mit Genehmigung verwendet. *Bibliografie der Forschungspublikationen zur Transzendentalen Meditation®, zusammengestellt von Dr. Roger Chalmers MRCP(UK) MRCGP DRCOG
H6: Spalte A: Allgemeines Thema: Gesundheit, geistiges Potenzial, Sozialverhalten, Weltfrieden
H7: Spalte B: Fachrichtung und Verweis auf gesammelte Arbeiten (falls zutreffend): physiologisch, psychologisch, soziologisch
H8: Spalte C: Fachgebiet: akademische Leistung, affektiv, biochemisch, kardiovaskulär, kognitiv, Persönlichkeitsentwicklung, EEG, elektrophysiologisch, Bildung, elektrophysiologisch, Gesundheit, Intelligenz, Lernen, metabolisch, Motorik und Wahrnehmung, physiologische Effizienz und Stabilität, Produktivität und Lebensqualität, Rehabilitation, Forschungsübersicht
H9: Spalte D: Spezifische Ergebnisse
H10: Spalte E: Randomisierte kontrollierte Studie / Meta-Analyse
H11: Spalte F: Erscheinungsjahr
H12: Spalte G: s = Zusammenfassung vorhanden
H13: Spalte H: Quellenangabe/Abstract/Zusammenfassung
A14: ALLGEMEINES THEMA | B14: FACHRICHTUNG und Verweis auf gesammelte Arbeiten | C14: FACHGEBIET | D14: SPEZIFISCHE ERGEBNISSE | E14: RCT /META | F14: JAHR
A15: Sozialverhalten | B15: Soziologisch CPVol 3Pg 2093 | C15: Rehabilitation | D15: Verringerte Insomnie – TM im Strafvollzug | F15: 1978 | G15: s | H15: Abrams AI, Siegel LM. The Transcendental Meditation program and rehabilitation at Folsom State Prison: a cross-validation study. Criminal Justice and Behavior 1978 5(1):3-20. Das Programm der Transzendentalen Meditation wurde in einem Hochsicherheitsgefängnis mittels eines Kreuzvalidierungsdesigns untersucht. Zwischen der Gruppe der Transzendentalen Meditation und der Kontrollgruppe wurden über alle Inventare hinweg signifikante Unterschiede festgestellt, die auf eine Verringerung von Angst, Neurotizismus, Feindseligkeit und Insomnie, weniger Verhaltensverstöße, verringerten Groll, verringerten Negativismus und verringerte Reizbarkeit sowie verbesserte Schlafmuster (verkürzte Einschlafzeit, weniger nächtliches Erwachen, verbesserte Schlafqualität) hinwiesen.
A16: Sozialverhalten | B16: Soziologisch CPVol 3Pg 2104 | C16: Rehabilitation | D16: TM im Strafvollzug | F16: 1979 | G16: s | H16: Abrams AI, Siegel LM. Transcendental Meditation and rehabilitation at Folsom Prison: response to a critique. Criminal Justice and Behavior 1979 6(1):13-21. Die im vorangegangenen Beitrag berichteten Vorteile der Transzendentalen Meditation erwiesen sich als nicht auf einen Selektionsbias oder eine Tendenz der Probanden zu sozial erwünschten, unwahren Antworten zurückführbar. Der Artikel antwortet auf den Einwand, die Befunde von Abrams und Siegel zum TM-Programm im Folsom State Prison seien auf Rosenthal-Versuchsleitereffekte zurückzuführen und die Daten seien von den Autoren allzu sparsam interpretiert worden. Die Autoren wiesen darauf hin, dass Rosenthal-Effekte nicht derart allgegenwärtig sind, dass vielversprechende Behandlungen in jedem denkbaren Fall abgetan werden sollten. Zudem zeigen die Daten der EPI-Lügenskala, dass die Behandlung die ohnehin geringe Neigung der Insassen zu sozial erwünschten, unwahren Antworten eher noch verringerte. In einer Meta-Analyse der Daten fanden sich keine konsistenten Zusammenhänge zwischen den Werten der Lügenskala und den Kriteriumsvariablen. Abschließend wurde die potenzielle Kosteneffektivität des Programms, die vom Kritiker infrage gestellt worden war, durch eine Analyse vorläufiger Rückfallquoten entlassener Teilnehmer gestützt.
A17: Gesundheit | B17: Physiologisch | C17: Kardiovaskulär | D17: Verringerter Bluthochdruck | F17: 1981 | G17: s | H17: Agarwal BL, Kharbanda A. Effect of transcendental meditation on mild and moderate hypertension. Journal of the Association of Physicians of India 1981 29:591-596. Bei Probanden mit leichtem und mittelschwerem Bluthochdruck wurden nach sechsmonatiger Praxis der Technik der Transzendentalen Meditation Senkungen des systolischen und diastolischen Blutdrucks festgestellt. Es wird nahegelegt, dass die Transzendentale Meditation in solchen Fällen als primäre Behandlung eingesetzt werden kann. Die Senkung des hohen Blutdrucks ist von großer Bedeutung für die Prävention von Herz-Kreislauf-Erkrankungen. Sechzehn Patienten mit leichter bis mittelschwerer essenzieller Hypertonie absolvierten ein sorgfältig überwachtes Programm der Transzendentalen Meditation (TM). Nach sechs Monaten kam es zu hochsignifikanten Senkungen des mittleren systolischen, diastolischen und arteriellen Mitteldrucks um 16,75, 9,81 bzw. 12,12. Zehn (62,5 %) der 16 Patienten galten als zufriedenstellend ansprechend, da sie eine Senkung des arteriellen Mitteldrucks um 15 mmHg oder mehr oder einen diastolischen Blutdruck von weniger als 90 mmHg zeigten. Die Ergebnisse sind mit einer medikamentösen Behandlung vergleichbar. Der größte Teil der Drucksenkung erfolgte in den ersten beiden Monaten. Nahezu alle Probanden berichteten von einem Gefühl des Wohlbefindens.
A18: Geistiges Potenzial | B18: Psychologisch: Übersicht CPVol 6 Pg 4385 | C18: Forschungsübersicht | D18: Übersicht der Wirkungen auf Individuum & Gesellschaft | F18: 1994 | G18: s | H18: Alexander CN. Transcendental Meditation. In RJ Corsini (ed.), Encyclopedia of Psychology (pp.5465-5466). New York: Wiley Interscience, 1994. Dieser Beitrag bietet eine Einführung in das Programm der Transzendentalen Meditation und die wichtigsten wissenschaftlichen Forschungsergebnisse zu seinen Wirkungen für das Individuum und die Gesellschaft.
A19: Geistiges Potenzial & Gesundheit | B19: Psychologisch: Übersicht CPVol5 Pg3399 | C19: Persönlichkeitsentwicklung | D19: TC | F19: 1986 | G19: s | H19: Alexander CN, Cranson RW, Boyer RW, Orme-Johnson DW. Transcendental Consciousness: a fourth state of consciousness beyond sleep, dreaming, and waking. In J Gackenbach (ed.), Sleep and Dreams: A Sourcebook (pp.282-312). New York: Garland Publishing, 1986. Es wird physiologische Forschung besprochen, die darauf hinweist, dass das transzendentale Bewusstsein ein einzigartiger vierter Hauptbewusstseinszustand ist.
